"""
Tests for error handling functionality.
"""
import os
import sys
import tempfile
import pytest

# Import the module path for testing
sys.path.append(os.path.join(os.path.dirname(__file__), "../../src"))

# Create sample problematic code for testing
PROBLEMATIC_CODE = """
def will_raise_exception():
    # This function will raise a ZeroDivisionError
    return 1 / 0

def another_problematic_function():
    # This function will raise a TypeError
    return "text" + 5
"""

def test_error_handling_with_real_exceptions():
    """Test error handling with real exceptions."""
    try:
        # Import the error handling module - if not available, skip the test
        from complexity.gitgit.integration.error_handler import handle_error, get_fallback_action
    except ImportError:
        pytest.skip("Error handler module not available")
    
    # Test with real exceptions
    try:
        # Try to divide by zero - will raise ZeroDivisionError
        result = 1 / 0
        # Should not reach here
        assert False, "Expected exception was not raised"
    except ZeroDivisionError as e:
        # Should handle the error
        error_info = handle_error(e, "division operation")
        
        # Verify error info structure
        assert "error_type" in error_info
        assert "error_message" in error_info
        assert "error_context" in error_info
        assert error_info["error_type"] == "ZeroDivisionError"
        assert "division" in error_info["error_context"]

def test_fallback_mechanism():
    """Test the fallback mechanism with real functions."""
    try:
        # Import the error handling module - if not available, skip the test
        from complexity.gitgit.integration.error_handler import handle_error, get_fallback_action
    except ImportError:
        pytest.skip("Error handler module not available")
    
    # Define real functions that can be used for testing
    def primary_function(x):
        """A function that will raise an exception for certain inputs."""
        if x == 0:
            raise ValueError("Cannot process zero")
        return 10 / x
    
    def fallback_function(x):
        """A fallback function that handles the case differently."""
        if x == 0:
            return float('inf')  # Return infinity instead of raising error
        return 10 / x
    
    # Test with a value that causes an exception
    try:
        # Try with a value that will cause an error
        result = primary_function(0)
        # Should not reach here
        assert False, "Expected exception was not raised"
    except ValueError as e:
        # Should handle the error and suggest using the fallback
        error_info = handle_error(e, "primary function")
        
        # Now use the fallback approach
        result = fallback_function(0)
        
        # Verify fallback worked
        assert result == float('inf')
        
        # Try a normal case
        normal_result = primary_function(5)
        assert normal_result == 2  # 10/5 = 2

def test_error_logging():
    """Test error logging functionality."""
    try:
        # Import the error handling module - if not available, skip the test
        from complexity.gitgit.integration.error_handler import log_error
    except ImportError:
        pytest.skip("Error handler module not available")
        
    # Create a temporary log file
    with tempfile.NamedTemporaryFile(mode="w+", delete=False) as f:
        log_path = f.name
    
    try:
        # Generate a real exception
        try:
            # This will raise TypeError
            result = "string" + 123
        except TypeError as e:
            # Log the error to our temp file
            log_error(e, "string concatenation", log_file=log_path)
            
            # Verify the log file contains error information
            with open(log_path, 'r') as log_file:
                log_content = log_file.read()
                assert "TypeError" in log_content
                assert "string concatenation" in log_content
    finally:
        # Clean up
        os.unlink(log_path)

if __name__ == "__main__":
    # Run tests manually
    test_error_handling_with_real_exceptions()
    test_fallback_mechanism()
    test_error_logging()